Workbook

Sheet Info_Schedule
B19: Corso | C19: A05003 Corporate finance e M&A
B20: Matricola | C20: 34226
B21: Nome | C21: BRYAN
B22: Cognome | C22: LATTUADA
B23: Assigment_n | C23: 3*

Sheet sensitivity_analysis
B3: Sensitive Analysis | C3: Historical Data | F3: Forecast Data
A4: x | B4: Voce (€ milioni) | C4: 2020 | D4: =+C4+1 -> 2021 | E4: =+D4+1 -> 2022 | F4: =+E4+1 -> 2023 | G4: =+F4+1 -> 2024 | H4: =+G4+1 -> 2025
A6: x | B6: Dashboard KPI's
B8: Live | C8: EV | D8: =+EV_EqV!F15 -> 16300.189 | F8: leggenda: | G8: 1 | H8: Base
B9: 1 | C9: EqV | D9: =+EV_EqV!F20 -> 16350.189 | G9: 2 | H9: Upside
G10: 3 | H10: Downside
B11: KPI area
B12: Profitability | C12: =+C59 -> 0.207 | D12: =+D59 -> 0.24338225 | E12: =+E59 -> 0.28225998 | F12: =+F59 -> 0.32116869 | G12: =+G59 -> 0.30812423 | H12: =+H59 -> 0.33382148
B13: Credit Risk | C13: =+C74 -> 0.048309179 | D13: =+D74 -> 0.80597199 | E13: =+E74 -> 1.7251274 | F13: =+F74 -> 1.3504172 | G13: =+G74 -> 0.61804675 | H13: =+H74 -> 0.25094527
B14: Liquidity | C14: =+C89 -> 0 | D14: =+D89 -> -0.77746267 | E14: =+E89 -> -1.066606 | F14: =+F89 -> 0.036440627 | G14: =+G89 -> 0.84229105 | H14: =+H89 -> 0.81300069
B15: Valuation (EBITDAx) | C15: =+C106 -> 0 | D15: =+D106 -> 0 | E15: =+E106 -> 0 | F15: =+F106 -> 0 | G15: =+G106 -> 0 | H15: =+H106 -> 15.748975
B16: ROIC | C16: =+C110 -> 0 | D16: =+D110 -> 0.15772919 | E16: =+E110 -> 0.12901118 | F16: =+F110 -> 0.14849529 | G16: =+G110 -> 0.14457558 | H16: =+H110 -> 0.1926718
A19: x | B19: Data Visualitation
A55: x | B55: Indici di Redditività
B57: Revenues | C57: =+'3_statement_model'!C71 -> 5000 | D57: =+'3_statement_model'!D73 -> 5764.8 | E57: =+'3_statement_model'!E73 -> 6567.984 | F57: =+'3_statement_model'!F73 -> 7483.3027 | G57: =+'3_statement_model'!G73 -> 7413.0047 | H57: =+'3_statement_model'!H73 -> 8003.6642
B58: EBITDA | C58: =+'3_statement_model'!C82 -> 1035 | D58: =+'3_statement_model'!D82 -> 1403.05 | E58: =+'3_statement_model'!E82 -> 1853.879 | F58: =+'3_statement_model'!F82 -> 2403.4025 | G58: =+'3_statement_model'!G82 -> 2284.1263 | H58: =+'3_statement_model'!H82 -> 2671.795
B59: EBITDA% | C59: =+C58/C57 -> 0.207 | D59: =+D58/D57 -> 0.24338225 | E59: =+E58/E57 -> 0.28225998 | F59: =+F58/F57 -> 0.32116869 | G59: =+G58/G57 -> 0.30812423 | H59: =+H58/H57 -> 0.33382148
B61: Revenues | C61: =+C57 -> 5000 | D61: =+'3_statement_model'!D73 -> 5764.8 | E61: =+'3_statement_model'!E73 -> 6567.984 | F61: =+'3_statement_model'!F73 -> 7483.3027 | G61: =+'3_statement_model'!G73 -> 7413.0047 | H61: =+'3_statement_model'!H73 -> 8003.6642
B62: EBIT | C62: =+'3_statement_model'!C88 -> 655 | D62: =+'3_statement_model'!D88 -> 985.05 | E62: =+'3_statement_model'!E88 -> 1394.079 | F62: =+'3_statement_model'!F88 -> 1851.6425 | G62: =+'3_statement_model'!G88 -> 1622.0143 | H62: =+'3_statement_model'!H88 -> 1877.2606
B63: EBIT% | C63: =+C62/C61 -> 0.131 | D63: =+D62/D61 -> 0.17087323 | E63: =+E62/E61 -> 0.21225371 | F63: =+F62/F61 -> 0.24743654 | G63: =+G62/G61 -> 0.2188066 | H63: =+H62/H61 -> 0.23455015
B65: Revenues | C65: =+C57 -> 5000 | D65: =+'3_statement_model'!D73 -> 5764.8 | E65: =+'3_statement_model'!E73 -> 6567.984 | F65: =+'3_statement_model'!F73 -> 7483.3027 | G65: =+'3_statement_model'!G73 -> 7413.0047 | H65: =+'3_statement_model'!H73 -> 8003.6642
B66: Net Revenues | C66: =+'3_statement_model'!C97 -> 375.1 | D66: =+'3_statement_model'!D97 -> 554.931 | E66: =+'3_statement_model'!E97 -> 808.52898 | F66: =+'3_statement_model'!F97 -> 1064.3184 | G66: =+'3_statement_model'!G97 -> 949.84889 | H66: =+'3_statement_model'!H97 -> 1108.1016
B67: Net Revenues% | C67: =+C66/C65 -> 0.07502 | D67: =+D66/D65 -> 0.096261969 | E67: =+E66/E65 -> 0.12310155 | F67: =+F66/F65 -> 0.14222575 | G67: =+G66/G65 -> 0.12813278 | H67: =+H66/H65 -> 0.13844928
A70: x | B70: Indici di sostenibilità
B72: PFN | C72: =+ABS(+'3_statement_model'!C113-'3_statement_model'!C103) -> 50 | D72: =+ABS(+'3_statement_model'!D113-'3_statement_model'!D103) -> 1130.819 | E72: =+ABS(+'3_statement_model'!E113-'3_statement_model'!E103) -> 3198.1775 | F72: =+ABS(+'3_statement_model'!F113-'3_statement_model'!F103) -> 3245.596 | G72: =+ABS(+'3_statement_model'!G113-'3_statement_model'!G103) -> 1411.6969 | H72: =+ABS(+'3_statement_model'!H113-'3_statement_model'!H103) -> 670.47431
B73: EBITDA | C73: =+C58 -> 1035 | D73: =+D58 -> 1403.05 | E73: =+E58 -> 1853.879 | F73: =+F58 -> 2403.4025 | G73: =+G58 -> 2284.1263 | H73: =+H58 -> 2671.795
B74: Net Debt/EBITA | C74: =+C72/C73 -> 0.048309179 | D74: =+D72/D73 -> 0.80597199 | E74: =+E72/E73 -> 1.7251274 | F74: =+F72/F73 -> 1.3504172 | G74: =+G72/G73 -> 0.61804675 | H74: =+H72/H73 -> 0.25094527
B76: Net Debt
B77: Equity
B78: Leverage (Fixed data) | C78: 0.6
B80: Debt Service Coverage Ratio
B81: EBITDA | C81: =+C58 -> 1035 | D81: =+D73 -> 1403.05 | E81: =+E73 -> 1853.879 | F81: =+F73 -> 2403.4025 | G81: =+G73 -> 2284.1263 | H81: =+H73 -> 2671.795
B82: Oneri Finanziari | C82: =+'3_statement_model'!C91 -> 70 | D82: =+'3_statement_model'!D91 -> 120 | E82: =+'3_statement_model'!E91 -> 120 | F82: =+'3_statement_model'!F91 -> 120 | G82: =+'3_statement_model'!G91 -> 120 | H82: =+'3_statement_model'!H91 -> 120
C83: =+C81/C82 -> 14.785714 | D83: =+D81/D82 -> 11.692083 | E83: =+E81/E82 -> 15.448992 | F83: =+F81/F82 -> 20.028354 | G83: =+G81/G82 -> 19.034386 | H83: =+H81/H82 -> 22.264958
A85: x | B85: Metriche di Efficienza del Capitale e Liquidità
B87: Operating Income (FCFF) | C87: =+'3_statement_model'!C135 -> 0 | D87: =+'3_statement_model'!D135 -> -1090.819 | E87: =+'3_statement_model'!E135 -> -1977.3585 | F87: =+'3_statement_model'!F135 -> 87.581495 | G87: =+'3_statement_model'!G135 -> 1923.8992 | H87: =+'3_statement_model'!H135 -> 2172.1712
B88: EBITDA | C88: =+C58 -> 1035 | D88: =+D58 -> 1403.05 | E88: =+E58 -> 1853.879 | F88: =+F58 -> 2403.4025 | G88: =+G58 -> 2284.1263 | H88: =+H58 -> 2671.795
B89: Cash Conversion Rate | C89: =+C87/C88 -> 0 | D89: =+D87/D88 -> -0.77746267 | E89: =+E87/E88 -> -1.066606 | F89: =+F87/F88 -> 0.036440627 | G89: =+G87/G88 -> 0.84229105 | H89: =+H87/H88 -> 0.81300069
B91: CapEx | D91: =+'3_statement_model'!D163 -> 1785 | E91: =+'3_statement_model'!E163 -> 3123.5 | F91: =+'3_statement_model'!F163 -> 1508.2 | G91: =+'3_statement_model'!G163 -> -0.028 | H91: =+'3_statement_model'!H163 -> -0.1136
B92: Revenues | C92: =+C57 -> 5000 | D92: =+D57 -> 5764.8 | E92: =+E57 -> 6567.984 | F92: =+F57 -> 7483.3027 | G92: =+G57 -> 7413.0047 | H92: =+H57 -> 8003.6642
...

Sheet 3_statement_model
F3: Forecast Periods
A4: x | B4: Voce (€ milioni) | C4: 2020 | D4: =+C4+1 -> 2021 | E4: =+D4+1 -> 2022 | F4: =+E4+1 -> 2023 | G4: =+F4+1 -> 2024 | H4: =+G4+1 -> 2025
A6: x | B6: Assumptions
A8: x | B8: Live Case
B9: revenues | D9: =+CHOOSE(sensitivity_analysis!$B$9,'3_statement_model'!D24,'3_statement_model'!D39,'3_statement_model'!D54) -> 0.14 | E9: =+CHOOSE(sensitivity_analysis!$B$9,'3_statement_model'!E24,'3_statement_model'!E39,'3_statement_model'!E54) -> 0.14 | F9: =+CHOOSE(sensitivity_analysis!$B$9,'3_statement_model'!F24,'3_statement_model'!F39,'3_statement_model'!F54) -> 0.14 | G9: =+CHOOSE(sensitivity_analysis!$B$9,'3_statement_model'!G24,'3_statement_model'!G39,'3_statement_model'!G54) -> -0.01 | H9: =+CHOOSE(sensitivity_analysis!$B$9,'3_statement_model'!H24,'3_statement_model'!H39,'3_statement_model'!H54) -> 0.08
B10: other incomes | D10: =+CHOOSE(sensitivity_analysis!$B$9,'3_statement_model'!D25,'3_statement_model'!D40,'3_statement_model'!D55) -> 0.08 | E10: =+CHOOSE(sensitivity_analysis!$B$9,'3_statement_model'!E25,'3_statement_model'!E40,'3_statement_model'!E55) -> 0.08 | F10: =+CHOOSE(sensitivity_analysis!$B$9,'3_statement_model'!F25,'3_statement_model'!F40,'3_statement_model'!F55) -> 0.08 | G10: =+CHOOSE(sensitivity_analysis!$B$9,'3_statement_model'!G25,'3_statement_model'!G40,'3_statement_model'!G55) -> 0.05 | H10: =+CHOOSE(sensitivity_analysis!$B$9,'3_statement_model'!H25,'3_statement_model'!H40,'3_statement_model'!H55) -> 0.05
B11: COGS | D11: =+CHOOSE(sensitivity_analysis!$B$9,'3_statement_model'!D26,'3_statement_model'!D41,'3_statement_model'!D56) -> 0.12 | E11: =+CHOOSE(sensitivity_analysis!$B$9,'3_statement_model'!E26,'3_statement_model'!E41,'3_statement_model'!E56) -> 0.11 | F11: =+CHOOSE(sensitivity_analysis!$B$9,'3_statement_model'!F26,'3_statement_model'!F41,'3_statement_model'!F56) -> 0.1 | G11: =+CHOOSE(sensitivity_analysis!$B$9,'3_statement_model'!G26,'3_statement_model'!G41,'3_statement_model'!G56) -> -0.03 | H11: =+CHOOSE(sensitivity_analysis!$B$9,'3_statement_model'!H26,'3_statement_model'!H41,'3_statement_model'!H56) -> 0.05
B12: salari | D12: =+CHOOSE(sensitivity_analysis!$B$9,'3_statement_model'!D27,'3_statement_model'!D42,'3_statement_model'!D57) -> 0.07 | E12: =+CHOOSE(sensitivity_analysis!$B$9,'3_statement_model'!E27,'3_statement_model'!E42,'3_statement_model'!E57) -> 0.07 | F12: =+CHOOSE(sensitivity_analysis!$B$9,'3_statement_model'!F27,'3_statement_model'!F42,'3_statement_model'!F57) -> 0.07 | G12: =+CHOOSE(sensitivity_analysis!$B$9,'3_statement_model'!G27,'3_statement_model'!G42,'3_statement_model'!G57) -> 0.03 | H12: =+CHOOSE(sensitivity_analysis!$B$9,'3_statement_model'!H27,'3_statement_model'!H42,'3_statement_model'!H57) -> 0.03
B13: oneri sociali | D13: =+CHOOSE(sensitivity_analysis!$B$9,'3_statement_model'!D28,'3_statement_model'!D43,'3_statement_model'!D58) -> 0.045 | E13: =+CHOOSE(sensitivity_analysis!$B$9,'3_statement_model'!E28,'3_statement_model'!E43,'3_statement_model'!E58) -> 0.045 | F13: =+CHOOSE(sensitivity_analysis!$B$9,'3_statement_model'!F28,'3_statement_model'!F43,'3_statement_model'!F58) -> 0.045 | G13: =+CHOOSE(sensitivity_analysis!$B$9,'3_statement_model'!G28,'3_statement_model'!G43,'3_statement_model'!G58) -> 0.045 | H13: =+CHOOSE(sensitivity_analysis!$B$9,'3_statement_model'!H28,'3_statement_model'!H43,'3_statement_model'!H58) -> 0.045
B14: accantonamento TFR | D14: =+CHOOSE(sensitivity_analysis!$B$9,'3_statement_model'!D29,'3_statement_model'!D44,'3_statement_model'!D59) -> 0.05 | E14: =+CHOOSE(sensitivity_analysis!$B$9,'3_statement_model'!E29,'3_statement_model'!E44,'3_statement_model'!E59) -> 0.05 | F14: =+CHOOSE(sensitivity_analysis!$B$9,'3_statement_model'!F29,'3_statement_model'!F44,'3_statement_model'!F59) -> 0.05 | G14: =+CHOOSE(sensitivity_analysis!$B$9,'3_statement_model'!G29,'3_statement_model'!G44,'3_statement_model'!G59) -> 0.05 | H14: =+CHOOSE(sensitivity_analysis!$B$9,'3_statement_model'!H29,'3_statement_model'!H44,'3_statement_model'!H59) -> 0.05
B15: tangibles assets | D15: =+CHOOSE(sensitivity_analysis!$B$9,'3_statement_model'!D30,'3_statement_model'!D45,'3_statement_model'!D60) -> 0.1 | E15: =+CHOOSE(sensitivity_analysis!$B$9,'3_statement_model'!E30,'3_statement_model'!E45,'3_statement_model'!E60) -> 0.1 | F15: =+CHOOSE(sensitivity_analysis!$B$9,'3_statement_model'!F30,'3_statement_model'!F45,'3_statement_model'!F60) -> 0.2 | G15: =+CHOOSE(sensitivity_analysis!$B$9,'3_statement_model'!G30,'3_statement_model'!G45,'3_statement_model'!G60) -> 0.2 | H15: =+CHOOSE(sensitivity_analysis!$B$9,'3_statement_model'!H30,'3_statement_model'!H45,'3_statement_model'!H60) -> 0.2
B16: intangibles assets | D16: =+CHOOSE(sensitivity_analysis!$B$9,'3_statement_model'!D31,'3_statement_model'!D46,'3_statement_model'!D61) -> 0.1 | E16: =+CHOOSE(sensitivity_analysis!$B$9,'3_statement_model'!E31,'3_statement_model'!E46,'3_statement_model'!E61) -> 0.1 | F16: =+CHOOSE(sensitivity_analysis!$B$9,'3_statement_model'!F31,'3_statement_model'!F46,'3_statement_model'!F61) -> 0.2 | G16: =+CHOOSE(sensitivity_analysis!$B$9,'3_statement_model'!G31,'3_statement_model'!G46,'3_statement_model'!G61) -> 0.2 | H16: =+CHOOSE(sensitivity_analysis!$B$9,'3_statement_model'!H31,'3_statement_model'!H46,'3_statement_model'!H61) -> 0.2
B17: proventi finanziari | D17: =+CHOOSE(sensitivity_analysis!$B$9,'3_statement_model'!D32,'3_statement_model'!D47,'3_statement_model'!D62) -> 30 | E17: =+CHOOSE(sensitivity_analysis!$B$9,'3_statement_model'!E32,'3_statement_model'!E47,'3_statement_model'!E62) -> 30 | F17: =+CHOOSE(sensitivity_analysis!$B$9,'3_statement_model'!F32,'3_statement_model'!F47,'3_statement_model'!F62) -> 30 | G17: =+CHOOSE(sensitivity_analysis!$B$9,'3_statement_model'!G32,'3_statement_model'!G47,'3_statement_model'!G62) -> 30 | H17: =+CHOOSE(sensitivity_analysis!$B$9,'3_statement_model'!H32,'3_statement_model'!H47,'3_statement_model'!H62) -> 30
B18: oneri finanziari | D18: =+CHOOSE(sensitivity_analysis!$B$9,'3_statement_model'!D33,'3_statement_model'!D48,'3_statement_model'!D63) -> 120 | E18: =+CHOOSE(sensitivity_analysis!$B$9,'3_statement_model'!E33,'3_statement_model'!E48,'3_statement_model'!E63) -> 120 | F18: =+CHOOSE(sensitivity_analysis!$B$9,'3_statement_model'!F33,'3_statement_model'!F48,'3_statement_model'!F63) -> 120 | G18: =+CHOOSE(sensitivity_analysis!$B$9,'3_statement_model'!G33,'3_statement_model'!G48,'3_statement_model'!G63) -> 120 | H18: =+CHOOSE(sensitivity_analysis!$B$9,'3_statement_model'!H33,'3_statement_model'!H48,'3_statement_model'!H63) -> 120
B19: oneri gestione straordinaria | D19: =+CHOOSE(sensitivity_analysis!$B$9,'3_statement_model'!D34,'3_statement_model'!D49,'3_statement_model'!D64) -> 0 | E19: =+CHOOSE(sensitivity_analysis!$B$9,'3_statement_model'!E34,'3_statement_model'!E49,'3_statement_model'!E64) -> 0 | F19: =+CHOOSE(sensitivity_analysis!$B$9,'3_statement_model'!F34,'3_statement_model'!F49,'3_statement_model'!F64) -> -45 | G19: =+CHOOSE(sensitivity_analysis!$B$9,'3_statement_model'!G34,'3_statement_model'!G49,'3_statement_model'!G64) -> 0 | H19: =+CHOOSE(sensitivity_analysis!$B$9,'3_statement_model'!H34,'3_statement_model'!H49,'3_statement_model'!H64) -> 0
B20: tax rate | C20: 0.38 | D20: =+CHOOSE(sensitivity_analysis!$B$9,'3_statement_model'!D35,'3_statement_model'!D50,'3_statement_model'!D65) -> 0.38 | E20: =+CHOOSE(sensitivity_analysis!$B$9,'3_statement_model'!E35,'3_statement_model'!E50,'3_statement_model'!E65) -> 0.38 | F20: =+CHOOSE(sensitivity_analysis!$B$9,'3_statement_model'!F35,'3_statement_model'!F50,'3_statement_model'!F65) -> 0.38 | G20: =+CHOOSE(sensitivity_analysis!$B$9,'3_statement_model'!G35,'3_statement_model'!G50,'3_statement_model'!G65) -> 0.38 | H20: =+CHOOSE(sensitivity_analysis!$B$9,'3_statement_model'!H35,'3_statement_model'!H50,'3_statement_model'!H65) -> 0.38
B21: liquidazione TFR | D21: =+CHOOSE(sensitivity_analysis!$B$9,'3_statement_model'!D36,'3_statement_model'!D51,'3_statement_model'!D66) -> 0 | E21: =+CHOOSE(sensitivity_analysis!$B$9,'3_statement_model'!E36,'3_statement_model'!E51,'3_statement_model'!E66) -> 0 | F21: =+CHOOSE(sensitivity_analysis!$B$9,'3_statement_model'!F36,'3_statement_model'!F51,'3_statement_model'!F66) -> 0 | G21: =+CHOOSE(sensitivity_analysis!$B$9,'3_statement_model'!G36,'3_statement_model'!G51,'3_statement_model'!G66) -> -30 | H21: =+CHOOSE(sensitivity_analysis!$B$9,'3_statement_model'!H36,'3_statement_model'!H51,'3_statement_model'!H66) -> -30
A23: x | B23: Base Case
B24: revenues | D24: 0.14 | E24: 0.14 | F24: 0.14 | G24: -0.01 | H24: 0.08
B25: other incomes | D25: 0.08 | E25: 0.08 | F25: 0.08 | G25: 0.05 | H25: 0.05
B26: COGS | D26: 0.12 | E26: 0.11 | F26: 0.1 | G26: -0.03 | H26: 0.05
B27: salari | D27: 0.07 | E27: 0.07 | F27: 0.07 | G27: 0.03 | H27: 0.03
B28: oenri sociali | D28: 0.045 | E28: 0.045 | F28: 0.045 | G28: 0.045 | H28: 0.045
B29: accantonamento TFR | D29: 0.05 | E29: 0.05 | F29: 0.05 | G29: 0.05 | H29: 0.05
B30: tangibles assets | D30: 0.1 | E30: 0.1 | F30: 0.2 | G30: 0.2 | H30: 0.2
B31: itangibles assets | D31: 0.1 | E31: 0.1 | F31: 0.2 | G31: 0.2 | H31: 0.2
B32: proventi finanziari | D32: 30 | E32: 30 | F32: 30 | G32: 30 | H32: 30
B33: oneri finanziari | D33: 120 | E33: 120 | F33: 120 | G33: 120 | H33: 120
B34: oneri gestione straordinaria | F34: -45
B35: tax rate | C35: 0.38 | D35: 0.38 | E35: 0.38 | F35: 0.38 | G35: 0.38 | H35: 0.38
B36: liquidazione TFR | G36: -30 | H36: -30
A38: x | B38: Upside Case
B39: revenues | D39: 0.14 | E39: 0.15 | F39: 0.145 | G39: 0.06 | H39: 0.12
B40: other incomes | D40: 0.08 | E40: 0.08 | F40: 0.08 | G40: 0.05 | H40: 0.05
B41: COGS | D41: 0.12 | E41: 0.11 | F41: 0.1 | G41: -0.03 | H41: 0.05
B42: salari | D42: 0.07 | E42: 0.07 | F42: 0.07 | G42: 0.03 | H42: 0.03
B43: oenri sociali | D43: 0.045 | E43: 0.045 | F43: 0.045 | G43: 0.045 | H43: 0.045
B44: accantonamento TFR | D44: 0.05 | E44: 0.05 | F44: 0.05 | G44: 0.05 | H44: 0.05
B45: tangibles assets | D45: 0.1 | E45: 0.1 | F45: 0.2 | G45: 0.2 | H45: 0.2
B46: itangibles assets | D46: 0.1 | E46: 0.1 | F46: 0.2 | G46: 0.2 | H46: 0.2
...

Sheet EV_EqV
E3: Forecast Periods
B4: Voce (€ milioni) | C4: 1 | D4: =+C4+1 -> 2 | E4: =+D4+1 -> 3 | F4: =+E4+1 -> 4 | G4: =+F4+1 -> 5
A6: x | B6: Project Valuation
B8: uFCFF | C8: =+'3_statement_model'!D135 -> -1090.819 | D8: =+'3_statement_model'!E135 -> -1977.3585 | E8: =+'3_statement_model'!F135 -> 87.581495 | F8: =+'3_statement_model'!G135 -> 1923.8992 | G8: =+'3_statement_model'!H135 -> 2172.1712
B9: uDCF | C9: =+C8/(1+$C$42)^C4 -> -1016.0504 | D9: =+D8/(1+$C$42)^D4 -> -1715.5782 | E9: =+E8/(1+$C$42)^E4 -> 70.778282 | F9: =+F8/(1+$C$42)^F4 -> 1448.2133 | G9: =+G8/(1+$C$42)^G4 -> 1523.0242
B10: TV | G10: =+(+'3_statement_model'!H127)*(1+$C$30)/(C42-C30) -> 22805.012
B12: PFN | E12: Enterprise Value
B13: (+) financial debts | C13: =+'3_statement_model'!C113 -> 200 | E13: (+) NPV CF | F13: =+SUM(C9:G9) -> 310.38716
B14: (-) liquidity | C14: =-'3_statement_model'!C103 -> -250 | E14: (+) NPV TV | F14: =+G10/(1+$C$42)^G4 -> 15989.802
B15: PFN | C15: =SUM(C13:C14) -> -50 | E15: EV | F15: =SUM(F13:F14) -> 16300.189
E17: Equity Value
E18: (+) EV | F18: =+F15 -> 16300.189
E19: (-) PFN | F19: =-C15 -> 50
E20: EqV | F20: =SUM(F18:F19) -> 16350.189
A23: x | B23: Dati
B25: risk-free | C25: 0.035
B26: return-market | C26: 0.055
B27: B | C27: 1.2
B28: cost of debt | C28: 0.045
B29: leva finanziaria | C29: 0.6
B30: tasso crescita (g) | C30: 0.02
B31: Tax-Rate | C31: =+'3_statement_model'!C20 -> 0.38
B33: WACC
B35: D | C35: 0.6 | D35: =+C35/$C$37 -> 0.375 | E35: Kd | F35: =+C28*(1-C31) -> 0.0279
B36: E | C36: 1 | D36: =+C36/$C$37 -> 0.625 | E36: Ke | F36: =+C25+C27*(C26) -> 0.101
B37: Total | C37: =SUM(C35:C36) -> 1.6 | D37: =+C37/$C$37 -> 1
B38: leverage | C38: 0.6
B40: D weighted | C40: =+D35*F35 -> 0.0104625
B41: E weighted | C41: =+D36*F36 -> 0.063125
B42: WACC | C42: =SUM(C40:C41) -> 0.0735875
